Workbook

Sheet Lisez-moi
A1: Calcul du nombre de Reynolds — banc aéraulique ISO 5167 / Miller
A3: Objet
A4: Reproduit le calcul du logiciel de pilotage (core/banc.py, core/diaphragmes.py, core/fluide.py, core/air_humide.py) : ΔP mesuré + P amont + PT100 -> débit massique -> Re conduite et Re veine.
A6: Mode d'emploi
A7: 1. Onglet « Calcul Re » : saisir les cellules sur fond jaune, texte bleu (lectures capteurs, position de la vanne 3 voies).
A8: 2. Les paramètres du banc (texte bleu, fond blanc) sont ceux de config.json ; les modifier seulement si config.json change.
A9: 3. Le résultat retenu (encadré vert) utilise le capteur de la butée lue : ΔP ISO en butée ISO, ΔP Miller en butée Miller.
A10: 4. Onglet « Tableau ΔP-Re » : Re en fonction du ΔP pour les deux diaphragmes, aux conditions (P, T, HR) saisies dans « Calcul Re ».
A12: Code couleur
A13: Texte bleu : valeur saisie (entrée ou paramètre) — Texte noir : formule — Texte vert : lien vers un autre onglet — Fond jaune : à renseigner à chaque calcul.
A15: Points à connaître
A16: • ISO 5167 : le coefficient C (Reader-Harris-Gallagher, prises d'angle) dépend du Re, lui-même fonction du débit : calcul itératif (10 itérations depuis qm = 0,1 kg/s, comme le logiciel).
... A25: Exemple (valeurs par défaut) : 20 °C, P amont 300 Pa, HR 50 %, ΔP ISO 496 Pa -> Re conduite 26 868, Re veine 14 368.

Sheet Calcul Re
A1: Calcul du Re depuis les capteurs de pression
A2: Formules du logiciel de pilotage (core/banc.py, core/diaphragmes.py, core/fluide.py, core/air_humide.py)
A4: Entrées capteurs (à saisir) | B4: Valeur | D4: Unité | E4: Formule / source | G4: RÉSULTAT (capteur de la butée lue)
A5: Position lue de la vanne 3 voies | B5: ISO | E5: ISO ou Miller : choisit le capteur ΔP exploité | G5: Diaphragme exploité | H5: =$B$5 -> ISO
A6: ΔP ISO lu (capteur dp_iso_500) | B6: 496 | D6: Pa | E6: Lecture brute, avant correction du zéro | G6: ΔP exploité [Pa] | H6: =IF($B$5="ISO",$B$57,$C$57) -> 495.98
A7: ΔP Miller lu (capteur dp_diaph_500) | B7: 100 | D7: Pa | E7: Lecture brute, avant correction du zéro | G7: Débit massique [kg/s] | H7: =IF($B$5="ISO",$B$64,$C$64) -> 0.029191828
A8: P amont (capteur p_amont_500, relative) | B8: 300 | D8: Pa | E8: Pression effective amont ; non corrigée du zéro (comme le logiciel) | G8: Re conduite | H8: =IF($B$5="ISO",$B$65,$C$65) -> 26867.354
A9: Température PT100 | B9: 20 | D9: °C | G9: Re veine | H9: =IF($B$5="ISO",$B$66,$C$66) -> 14367.825
G11: ISO : diaphragme haut Re (> 5 000 Re conduite) ; Miller : bas Re
A12: Paramètres du banc (config.json) | B12: Valeur | D12: Unité | E12: Formule / source
A13: P atmosphérique (fixe) | B13: 101325 | D13: Pa | E13: config.json : patm_pa
A14: Humidité relative | B14: 50 | D14: % | E14: config.json : fluide.humidite_relative (0 = air sec)
A15: Zéro capteur ΔP ISO | B15: 0.02 | D15: Pa | E15: config.json : zero_capteurs.dp_iso_500 (apprentissage « Zéro capteurs »)
A16: Zéro capteur ΔP Miller | B16: 0.01 | D16: Pa | E16: config.json : zero_capteurs.dp_diaph_500
A17: γ (coefficient isentropique) | B17: 1.40273 | D17: - | E17: config.json : fluide.gamma
A18: R air sec | B18: 287.058 | D18: J/(kg·K) | E18: core/fluide.py : R_AIR
A19: Sutherland μ réf. | B19: 1.72e-05 | D19: Pa·s | E19: config.json : fluide.sutherland_mu_ref (air sec seulement)
A20: Sutherland T réf. | B20: 273.15 | D20: K | E20: config.json : fluide.sutherland_t_ref
A21: Sutherland S | B21: 110.4 | D21: K | E21: config.json : fluide.sutherland_s
A22: Seuil de bruit ΔP (débit nul en dessous) | B22: 0.3 | D22: Pa | E22: core/diaphragmes.py : ΔP < 0,3 Pa -> qm = 0
A25: Géométrie (config.json) | B25: ISO 5167 | C25: Miller | D25: Unité | E25: Source
A26: Diamètre intérieur conduite à 20 °C | B26: 76.6 | C26: 76.6 | D26: mm | E26: diaphragme_iso / diaphragme_miller.D20_mm
A27: Diamètre orifice à 20 °C | B27: 41.018 | C27: 21.113 | D27: mm | E27: diaphragme_iso / diaphragme_miller.d20_mm
A28: Dilatation conduite α | B28: 2.4e-05 | C28: 8e-05 | D28: 1/°C | E28: diaphragme_iso / diaphragme_miller.alpha_conduite
A29: Dilatation diaphragme α | B29: 2.4e-05 | C29: 1.7e-05 | D29: 1/°C | E29: diaphragme_iso / diaphragme_miller.alpha_diaphragme
A30: Hauteur veine H | B30: 0.05 | D30: m | E30: config.json : veine.hauteur_m
A31: Largeur veine W | B31: 0.175 | D31: m | E31: config.json : veine.largeur_m
A34: Propriétés de l'air | B34: Valeur | D34: Unité | E34: Formule / source
A35: P1 absolue amont | B35: =$B$13+$B$8 -> 101625 | D35: Pa | E35: P1 = P atm + P amont
A36: T absolue | B36: =$B$9+273.15 -> 293.15 | D36: K
A37: Pression de vapeur saturante Pvs | B37: =10^(IF($B$9>=0,7.625*$B$9/(241+$B$9),9.756*$B$9/(272.7+$B$9))+2.7877) -> 2355.0015 | D37: Pa | E37: Magnus-Tetens : 10^(7,625·t/(241+t)+2,7877) ; sous 0 °C : 9,756·t/(272,7+t)
A38: Pression partielle de vapeur Pv | B38: =$B$14/100*$B$37 -> 1177.5007 | D38: Pa | E38: Pv = HR·Pvs
A39: Humidité spécifique x | B39: =0.622*$B$38/($B$35-$B$38) -> 0.0072914256 | D39: kg/kg | E39: x = 0,622·Pv/(P1 − Pv)
A40: Volume spécifique v | B40: =461.24*(0.622+$B$39)*$B$36/$B$35 -> 0.83727499 | D40: m³/kg | E40: v = 461,24·(0,622 + x)·T/P1
A41: ρ air humide | B41: =(1+$B$39)/$B$40 -> 1.2030593 | D41: kg/m³ | E41: ρ = (1 + x)/v
A42: μ air humide | B42: =(17.1+0.048*$B$9)*0.000001 -> 1.806e-05 | D42: Pa·s | E42: μ = (17,1 + 0,048·t)·10⁻⁶
A43: ρ air sec | B43: =$B$35/($B$18*$B$36) -> 1.2076498 | D43: kg/m³ | E43: ρ = P1/(R·T)
A44: μ air sec (Sutherland) | B44: =$B$19*($B$36/$B$20)^1.5*($B$20+$B$21)/($B$36+$B$21) -> 1.817549e-05 | D44: Pa·s | E44: μ = μréf·(T/Tréf)^1,5·(Tréf + S)/(T + S)
A45: ρ retenue | B45: =IF($B$14>0,$B$41,$B$43) -> 1.2030593 | D45: kg/m³ | E45: Air humide si HR > 0, sinon air sec
A46: μ retenue | B46: =IF($B$14>0,$B$42,$B$44) -> 1.806e-05 | D46: Pa·s
...

Sheet Tableau ΔP-Re
A1: Re en fonction du ΔP corrigé, ISO 5167 et Miller
A2: Conditions (liens vers « Calcul Re ») :
A3: P1 abs [Pa] | B3: ='Calcul Re'!$B$35 -> 101625 | C3: t [°C] | D3: ='Calcul Re'!$B$9 -> 20 | E3: HR [%] | F3: ='Calcul Re'!$B$14 -> 50 | G3: ρ [kg/m³] | H3: ='Calcul Re'!$B$45 -> 1.2030593 | I3: μ [Pa·s] | J3: ='Calcul Re'!$B$46 -> 1.806e-05
I4: Itérations ISO : qm_k (k = 1…10), qm_0 = 0,1 kg/s
A5: ΔP corrigé [Pa] | B5: Miller qm [kg/s] | C5: Miller Re conduite | D5: Miller Re veine | E5: ISO qm [kg/s] | F5: ISO Re conduite | G5: ISO Re veine | I5: qm_1 | J5: qm_2 | K5: qm_3 | L5: qm_4 | M5: qm_5 | N5: qm_6 | O5: qm_7 | P5: qm_8 | Q5: qm_9 | R5: qm_10
A6: 0.5 | B6: =IF($A6<'Calcul Re'!$B$22,0,PI()*SQRT(2)/4*'Calcul Re'!$C$63*'Calcul Re'!$C$59^2*(1-(0.41+0.35*'Calcul Re'!$C$60^4)/'Calcul Re'!$B$17*($A6/'Calcul Re'!$B$35))*SQRT($A6)*SQRT('Calcul Re'!$B$45)/SQRT(1-'Calcul Re'!$C$60^4)) -> 0.00029816421 | C6: =4*B6/(PI()*'Calcul Re'!$B$26/1000*'Calcul Re'!$B$46) -> 274.42212 | D6: =B6*'Calcul Re'!$B$52/('Calcul Re'!$B$46*'Calcul Re'!$B$51) -> 146.75241 | E6: =IF($A6<'Calcul Re'!$B$22,0,R6) -> 0.0010578868 | F6: =4*E6/(PI()*'Calcul Re'!$B$26/1000*'Calcul Re'!$B$46) -> 973.64983 | G6: =E6*'Calcul Re'!$B$52/('Calcul Re'!$B$46*'Calcul Re'!$B$51) -> 520.67763 | I6: =(0.5961+0.0261*'Calcul Re'!$B$60^2-0.216*'Calcul Re'!$B$60^8+0.000521*(1000000*'Calcul Re'!$B$60/MAX(4*0.1/(PI()*'Calcul Re'!$B$58*'Calcul Re'!$B$46),100))^0.7+(0.0188+0.0063*(19000*'Calcul Re'!$B$60/MAX(4*0.1/(PI()*'Calcul Re'!$B$58*'Calcul Re'!$B$46),100))^0.8)*'Calcul Re'!$B$60^3.5*(1000000/MAX(4*0.1/(PI()*'Calcul Re'!$B$58*'Calcul Re'!$B$46),100))^0.3)*'Calcul Re'!$B$61*(1-(0.41+0.35*'Calcul Re'!$B$60^4)*$A6/('Calcul Re'!$B$17*'Calcul Re'!$B$35))*PI()*'Calcul Re'!$B$59^2/4*SQRT(2*MAX($A6,0)*'Calcul Re'!$B$45) -> 0.00092057539 | J6: =(0.5961+0.0261*'Calcul Re'!$B$60^2-0.216*'Calcul Re'!$B$60^8+0.000521*(1000000*'Calcul Re'!$B$60/MAX(4*I6/(PI()*'Calcul Re'!$B$58*'Calcul Re'!$B$46),100))^0.7+(0.0188+0.0063*(19000*'Calcul Re'!$B$60/MAX(4*I6/(PI()*'Calcul Re'!$B$58*'Calcul Re'!$B$46),100))^0.8)*'Calcul Re'!$B$60^3.5*(1000000/MAX(4*I6/(PI()*'Calcul Re'!$B$58*'Calcul Re'!$B$46),100))^0.3)*'Calcul Re'!$B$61*(1-(0.41+0.35*'Calcul Re'!$B$60^4)*$A6/('Calcul Re'!$B$17*'Calcul Re'!$B$35))*PI()*'Calcul Re'!$B$59^2/4*SQRT(2*MAX($A6,0)*'Calcul Re'!$B$45) -> 0.0010749117 | K6: =(0.5961+0.0261*'Calcul Re'!$B$60^2-0.216*'Calcul Re'!$B$60^8+0.000521*(1000000*'Calcul Re'!$B$60/MAX(4*J6/(PI()*'Calcul Re'!$B$58*'Calcul Re'!$B$46),100))^0.7+(0.0188+0.0063*(19000*'Calcul Re'!$B$60/MAX(4*J6/(PI()*'Calcul Re'!$B$58*'Calcul Re'!$B$46),100))^0.8)*'Calcul Re'!$B$60^3.5*(1000000/MAX(4*J6/(PI()*'Calcul Re'!$B$58*'Calcul Re'!$B$46),100))^0.3)*'Calcul Re'!$B$61*(1-(0.41+0.35*'Calcul Re'!$B$60^4)*$A6/('Calcul Re'!$B$17*'Calcul Re'!$B$35))*PI()*'Calcul Re'!$B$59^2/4*SQRT(2*MAX($A6,0)*'Calcul Re'!$B$45) -> 0.0010560632 | L6: =(0.5961+0.0261*'Calcul Re'!$B$60^2-0.216*'Calcul Re'!$B$60^8+0.000521*(1000000*'Calcul Re'!$B$60/MAX(4*K6/(PI()*'Calcul Re'!$B$58*'Calcul Re'!$B$46),100))^0.7+(0.0188+0.0063*(19000*'Calcul Re'!$B$60/MAX(4*K6/(PI()*'Calcul Re'!$B$58*'Calcul Re'!$B$46),100))^0.8)*'Calcul Re'!$B$60^3.5*(1000000/MAX(4*K6/(PI()*'Calcul Re'!$B$58*'Calcul Re'!$B$46),100))^0.3)*'Calcul Re'!$B$61*(1-(0.41+0.35*'Calcul Re'!$B$60^4)*$A6/('Calcul Re'!$B$17*'Calcul Re'!$B$35))*PI()*'Calcul Re'!$B$59^2/4*SQRT(2*MAX($A6,0)*'Calcul Re'!$B$45) -> 0.0010580854 | M6: =(0.5961+0.0261*'Calcul Re'!$B$60^2-0.216*'Calcul Re'!$B$60^8+0.000521*(1000000*'Calcul Re'!$B$60/MAX(4*L6/(PI()*'Calcul Re'!$B$58*'Calcul Re'!$B$46),100))^0.7+(0.0188+0.0063*(19000*'Calcul Re'!$B$60/MAX(4*L6/(PI()*'Calcul Re'!$B$58*'Calcul Re'!$B$46),100))^0.8)*'Calcul Re'!$B$60^3.5*(1000000/MAX(4*L6/(PI()*'Calcul Re'!$B$58*'Calcul Re'!$B$46),100))^0.3)*'Calcul Re'!$B$61*(1-(0.41+0.35*'Calcul Re'!$B$60^4)*$A6/('Calcul Re'!$B$17*'Calcul Re'!$B$35))*PI()*'Calcul Re'!$B$59^2/4*SQRT(2*MAX($A6,0)*'Calcul Re'!$B$45) -> 0.0010578652 | N6: =(0.5961+0.0261*'Calcul Re'!$B$60^2-0.216*'Calcul Re'!$B$60^8+0.000521*(1000000*'Calcul Re'!$B$60/MAX(4*M6/(PI()*'Calcul Re'!$B$58*'Calcul Re'!$B$46),100))^0.7+(0.0188+0.0063*(19000*'Calcul Re'!$B$60/MAX(4*M6/(PI()*'Calcul Re'!$B$58*'Calcul Re'!$B$46),100))^0.8)*'Calcul Re'!$B$60^3.5*(1000000/MAX(4*M6/(PI()*'Calcul Re'!$B$58*'Calcul Re'!$B$46),100))^0.3)*'Calcul Re'!$B$61*(1-(0.41+0.35*'Calcul Re'!$B$60^4)*$A6/('Calcul Re'!$B$17*'Calcul Re'!$B$35))*PI()*'Calcul Re'!$B$59^2/4*SQRT(2*MAX($A6,0)*'Calcul Re'!$B$45) -> 0.0010578891 | O6: =(0.5961+0.0261*'Calcul Re'!$B$60^2-0.216*'Calcul Re'!$B$60^8+0.000521*(1000000*'Calcul Re'!$B$60/MAX(4*N6/(PI()*'Calcul Re'!$B$58*'Calcul Re'!$B$46),100))^0.7+(0.0188+0.0063*(19000*'Calcul Re'!$B$60/MAX(4*N6/(PI()*'Calcul Re'!$B$58*'Calcul Re'!$B$46),100))^0.8)*'Calcul Re'!$B$60^3.5*(1000000/MAX(4*N6/(PI()*'Calcul Re'!$B$58*'Calcul Re'!$B$46),100))^0.3)*'Calcul Re'!$B$61*(1-(0.41+0.35*'Calcul Re'!$B$60^4)*$A6/('Calcul Re'!$B$17*'Calcul Re'!$B$35))*PI()*'Calcul Re'!$B$59^2/4*SQRT(2*MAX($A6,0)*'Calcul Re'!$B$45) -> 0.0010578865 | P6: =(0.5961+0.0261*'Calcul Re'!$B$60^2-0.216*'Calcul Re'!$B$60^8+0.000521*(1000000*'Calcul Re'!$B$60/MAX(4*O6/(PI()*'Calcul Re'!$B$58*'Calcul Re'!$B$46),100))^0.7+(0.0188+0.0063*(19000*'Calcul Re'!$B$60/MAX(4*O6/(PI()*'Calcul Re'!$B$58*'Calcul Re'!$B$46),100))^0.8)*'Calcul Re'!$B$60^3.5*(1000000/MAX(4*O6/(PI()*'Calcul Re'!$B$58*'Calcul Re'!$B$46),100))^0.3)*'Calcul Re'!$B$61*(1-(0.41+0.35*'Calcul Re'!$B$60^4)*$A6/('Calcul Re'!$B$17*'Calcul Re'!$B$35))*PI()*'Calcul Re'!$B$59^2/4*SQRT(2*MAX($A6,0)*'Calcul Re'!$B$45) -> 0.0010578868 | Q6: =(0.5961+0.0261*'Calcul Re'!$B$60^2-0.216*'Calcul Re'!$B$60^8+0.000521*(1000000*'Calcul Re'!$B$60/MAX(4*P6/(PI()*'Calcul Re'!$B$58*'Calcul Re'!$B$46),100))^0.7+(0.0188+0.0063*(19000*'Calcul Re'!$B$60/MAX(4*P6/(PI()*'Calcul Re'!$B$58*'Calcul Re'!$B$46),100))^0.8)*'Calcul Re'!$B$60^3.5*(1000000/MAX(4*P6/(PI()*'Calcul Re'!$B$58*'Calcul Re'!$B$46),100))^0.3)*'Calcul Re'!$B$61*(1-(0.41+0.35*'Calcul Re'!$B$60^4)*$A6/('Calcul Re'!$B$17*'Calcul Re'!$B$35))*PI()*'Calcul Re'!$B$59^2/4*SQRT(2*MAX($A6,0)*'Calcul Re'!$B$45) -> 0.0010578868 | R6: =(0.5961+0.0261*'Calcul Re'!$B$60^2-0.216*'Calcul Re'!$B$60^8+0.000521*(1000000*'Calcul Re'!$B$60/MAX(4*Q6/(PI()*'Calcul Re'!$B$58*'Calcul Re'!$B$46),100))^0.7+(0.0188+0.0063*(19000*'Calcul Re'!$B$60/MAX(4*Q6/(PI()*'Calcul Re'!$B$58*'Calcul Re'!$B$46),100))^0.8)*'Calcul Re'!$B$60^3.5*(1000000/MAX(4*Q6/(PI()*'Calcul Re'!$B$58*'Calcul Re'!$B$46),100))^0.3)*'Calcul Re'!$B$61*(1-(0.41+0.35*'Calcul Re'!$B$60^4)*$A6/('Calcul Re'!$B$17*'Calcul Re'!$B$35))*PI()*'Calcul Re'!$B$59^2/4*SQRT(2*MAX($A6,0)*'Calcul Re'!$B$45) -> 0.0010578868
A7: 1 | B7: =IF($A7<'Calcul Re'!$B$22,0,PI()*SQRT(2)/4*'Calcul Re'!$C$63*'Calcul Re'!$C$59^2*(1-(0.41+0.35*'Calcul Re'!$C$60^4)/'Calcul Re'!$B$17*($A7/'Calcul Re'!$B$35))*SQRT($A7)*SQRT('Calcul Re'!$B$45)/SQRT(1-'Calcul Re'!$C$60^4)) -> 0.00042166727 | C7: =4*B7/(PI()*'Calcul Re'!$B$26/1000*'Calcul Re'!$B$46) -> 388.09093 | D7: =B7*'Calcul Re'!$B$52/('Calcul Re'!$B$46*'Calcul Re'!$B$51) -> 207.53895 | E7: =IF($A7<'Calcul Re'!$B$22,0,R7) -> 0.0014511925 | F7: =4*E7/(PI()*'Calcul Re'!$B$26/1000*'Calcul Re'!$B$46) -> 1335.6376 | G7: =E7*'Calcul Re'!$B$52/('Calcul Re'!$B$46*'Calcul Re'!$B$51) -> 714.25743 | I7: =(0.5961+0.0261*'Calcul Re'!$B$60^2-0.216*'Calcul Re'!$B$60^8+0.000521*(1000000*'Calcul Re'!$B$60/MAX(4*0.1/(PI()*'Calcul Re'!$B$58*'Calcul Re'!$B$46),100))^0.7+(0.0188+0.0063*(19000*'Calcul Re'!$B$60/MAX(4*0.1/(PI()*'Calcul Re'!$B$58*'Calcul Re'!$B$46),100))^0.8)*'Calcul Re'!$B$60^3.5*(1000000/MAX(4*0.1/(PI()*'Calcul Re'!$B$58*'Calcul Re'!$B$46),100))^0.3)*'Calcul Re'!$B$61*(1-(0.41+0.35*'Calcul Re'!$B$60^4)*$A7/('Calcul Re'!$B$17*'Calcul Re'!$B$35))*PI()*'Calcul Re'!$B$59^2/4*SQRT(2*MAX($A7,0)*'Calcul Re'!$B$45) -> 0.0013018882 | J7: =(0.5961+0.0261*'Calcul Re'!$B$60^2-0.216*'Calcul Re'!$B$60^8+0.000521*(1000000*'Calcul Re'!$B$60/MAX(4*I7/(PI()*'Calcul Re'!$B$58*'Calcul Re'!$B$46),100))^0.7+(0.0188+0.0063*(19000*'Calcul Re'!$B$60/MAX(4*I7/(PI()*'Calcul Re'!$B$58*'Calcul Re'!$B$46),100))^0.8)*'Calcul Re'!$B$60^3.5*(1000000/MAX(4*I7/(PI()*'Calcul Re'!$B$58*'Calcul Re'!$B$46),100))^0.3)*'Calcul Re'!$B$61*(1-(0.41+0.35*'Calcul Re'!$B$60^4)*$A7/('Calcul Re'!$B$17*'Calcul Re'!$B$35))*PI()*'Calcul Re'!$B$59^2/4*SQRT(2*MAX($A7,0)*'Calcul Re'!$B$45) -> 0.0014652273 | K7: =(0.5961+0.0261*'Calcul Re'!$B$60^2-0.216*'Calcul Re'!$B$60^8+0.000521*(1000000*'Calcul Re'!$B$60/MAX(4*J7/(PI()*'Calcul Re'!$B$58*'Calcul Re'!$B$46),100))^0.7+(0.0188+0.0063*(19000*'Calcul Re'!$B$60/MAX(4*J7/(PI()*'Calcul Re'!$B$58*'Calcul Re'!$B$46),100))^0.8)*'Calcul Re'!$B$60^3.5*(1000000/MAX(4*J7/(PI()*'Calcul Re'!$B$58*'Calcul Re'!$B$46),100))^0.3)*'Calcul Re'!$B$61*(1-(0.41+0.35*'Calcul Re'!$B$60^4)*$A7/('Calcul Re'!$B$17*'Calcul Re'!$B$35))*PI()*'Calcul Re'!$B$59^2/4*SQRT(2*MAX($A7,0)*'Calcul Re'!$B$45) -> 0.0014500111 | L7: =(0.5961+0.0261*'Calcul Re'!$B$60^2-0.216*'Calcul Re'!$B$60^8+0.000521*(1000000*'Calcul Re'!$B$60/MAX(4*K7/(PI()*'Calcul Re'!$B$58*'Calcul Re'!$B$46),100))^0.7+(0.0188+0.0063*(19000*'Calcul Re'!$B$60/MAX(4*K7/(PI()*'Calcul Re'!$B$58*'Calcul Re'!$B$46),100))^0.8)*'Calcul Re'!$B$60^3.5*(1000000/MAX(4*K7/(PI()*'Calcul Re'!$B$58*'Calcul Re'!$B$46),100))^0.3)*'Calcul Re'!$B$61*(1-(0.41+0.35*'Calcul Re'!$B$60^4)*$A7/('Calcul Re'!$B$17*'Calcul Re'!$B$35))*PI()*'Calcul Re'!$B$59^2/4*SQRT(2*MAX($A7,0)*'Calcul Re'!$B$45) -> 0.0014512929 | M7: =(0.5961+0.0261*'Calcul Re'!$B$60^2-0.216*'Calcul Re'!$B$60^8+0.000521*(1000000*'Calcul Re'!$B$60/MAX(4*L7/(PI()*'Calcul Re'!$B$58*'Calcul Re'!$B$46),100))^0.7+(0.0188+0.0063*(19000*'Calcul Re'!$B$60/MAX(4*L7/(PI()*'Calcul Re'!$B$58*'Calcul Re'!$B$46),100))^0.8)*'Calcul Re'!$B$60^3.5*(1000000/MAX(4*L7/(PI()*'Calcul Re'!$B$58*'Calcul Re'!$B$46),100))^0.3)*'Calcul Re'!$B$61*(1-(0.41+0.35*'Calcul Re'!$B$60^4)*$A7/('Calcul Re'!$B$17*'Calcul Re'!$B$35))*PI()*'Calcul Re'!$B$59^2/4*SQRT(2*MAX($A7,0)*'Calcul Re'!$B$45) -> 0.001451184 | N7: =(0.5961+0.0261*'Calcul Re'!$B$60^2-0.216*'Calcul Re'!$B$60^8+0.000521*(1000000*'Calcul Re'!$B$60/MAX(4*M7/(PI()*'Calcul Re'!$B$58*'Calcul Re'!$B$46),100))^0.7+(0.0188+0.0063*(19000*'Calcul Re'!$B$60/MAX(4*M7/(PI()*'Calcul Re'!$B$58*'Calcul Re'!$B$46),100))^0.8)*'Calcul Re'!$B$60^3.5*(1000000/MAX(4*M7/(PI()*'Calcul Re'!$B$58*'Calcul Re'!$B$46),100))^0.3)*'Calcul Re'!$B$61*(1-(0.41+0.35*'Calcul Re'!$B$60^4)*$A7/('Calcul Re'!$B$17*'Calcul Re'!$B$35))*PI()*'Calcul Re'!$B$59^2/4*SQRT(2*MAX($A7,0)*'Calcul Re'!$B$45) -> 0.0014511933 | O7: =(0.5961+0.0261*'Calcul Re'!$B$60^2-0.216*'Calcul Re'!$B$60^8+0.000521*(1000000*'Calcul Re'!$B$60/MAX(4*N7/(PI()*'Calcul Re'!$B$58*'Calcul Re'!$B$46),100))^0.7+(0.0188+0.0063*(19000*'Calcul Re'!$B$60/MAX(4*N7/(PI()*'Calcul Re'!$B$58*'Calcul Re'!$B$46),100))^0.8)*'Calcul Re'!$B$60^3.5*(1000000/MAX(4*N7/(PI()*'Calcul Re'!$B$58*'Calcul Re'!$B$46),100))^0.3)*'Calcul Re'!$B$61*(1-(0.41+0.35*'Calcul Re'!$B$60^4)*$A7/('Calcul Re'!$B$17*'Calcul Re'!$B$35))*PI()*'Calcul Re'!$B$59^2/4*SQRT(2*MAX($A7,0)*'Calcul Re'!$B$45) -> 0.0014511925 | P7: =(0.5961+0.0261*'Calcul Re'!$B$60^2-0.216*'Calcul Re'!$B$60^8+0.000521*(1000000*'Calcul Re'!$B$60/MAX(4*O7/(PI()*'Calcul Re'!$B$58*'Calcul Re'!$B$46),100))^0.7+(0.0188+0.0063*(19000*'Calcul Re'!$B$60/MAX(4*O7/(PI()*'Calcul Re'!$B$58*'Calcul Re'!$B$46),100))^0.8)*'Calcul Re'!$B$60^3.5*(1000000/MAX(4*O7/(PI()*'Calcul Re'!$B$58*'Calcul Re'!$B$46),100))^0.3)*'Calcul Re'!$B$61*(1-(0.41+0.35*'Calcul Re'!$B$60^4)*$A7/('Calcul Re'!$B$17*'Calcul Re'!$B$35))*PI()*'Calcul Re'!$B$59^2/4*SQRT(2*MAX($A7,0)*'Calcul Re'!$B$45) -> 0.0014511925 | Q7: =(0.5961+0.0261*'Calcul Re'!$B$60^2-0.216*'Calcul Re'!$B$60^8+0.000521*(1000000*'Calcul Re'!$B$60/MAX(4*P7/(PI()*'Calcul Re'!$B$58*'Calcul Re'!$B$46),100))^0.7+(0.0188+0.0063*(19000*'Calcul Re'!$B$60/MAX(4*P7/(PI()*'Calcul Re'!$B$58*'Calcul Re'!$B$46),100))^0.8)*'Calcul Re'!$B$60^3.5*(1000000/MAX(4*P7/(PI()*'Calcul Re'!$B$58*'Calcul Re'!$B$46),100))^0.3)*'Calcul Re'!$B$61*(1-(0.41+0.35*'Calcul Re'!$B$60^4)*$A7/('Calcul Re'!$B$17*'Calcul Re'!$B$35))*PI()*'Calcul Re'!$B$59^2/4*SQRT(2*MAX($A7,0)*'Calcul Re'!$B$45) -> 0.0014511925 | R7: =(0.5961+0.0261*'Calcul Re'!$B$60^2-0.216*'Calcul Re'!$B$60^8+0.000521*(1000000*'Calcul Re'!$B$60/MAX(4*Q7/(PI()*'Calcul Re'!$B$58*'Calcul Re'!$B$46),100))^0.7+(0.0188+0.0063*(19000*'Calcul Re'!$B$60/MAX(4*Q7/(PI()*'Calcul Re'!$B$58*'Calcul Re'!$B$46),100))^0.8)*'Calcul Re'!$B$60^3.5*(1000000/MAX(4*Q7/(PI()*'Calcul Re'!$B$58*'Calcul Re'!$B$46),100))^0.3)*'Calcul Re'!$B$61*(1-(0.41+0.35*'Calcul Re'!$B$60^4)*$A7/('Calcul Re'!$B$17*'Calcul Re'!$B$35))*PI()*'Calcul Re'!$B$59^2/4*SQRT(2*MAX($A7,0)*'Calcul Re'!$B$45) -> 0.0014511925
A8: 2 | B8: =IF($A8<'Calcul Re'!$B$22,0,PI()*SQRT(2)/4*'Calcul Re'!$C$63*'Calcul Re'!$C$59^2*(1-(0.41+0.35*'Calcul Re'!$C$60^4)/'Calcul Re'!$B$17*($A8/'Calcul Re'!$B$35))*SQRT($A8)*SQRT('Calcul Re'!$B$45)/SQRT(1-'Calcul Re'!$C$60^4)) -> 0.00059632584 | C8: =4*B8/(PI()*'Calcul Re'!$B$26/1000*'Calcul Re'!$B$46) -> 548.84187 | D8: =B8*'Calcul Re'!$B$52/('Calcul Re'!$B$46*'Calcul Re'!$B$51) -> 293.50355 | E8: =IF($A8<'Calcul Re'!$B$22,0,R8) -> 0.00200322 | F8: =4*E8/(PI()*'Calcul Re'!$B$26/1000*'Calcul Re'!$B$46) -> 1843.7084 | G8: =E8*'Calcul Re'!$B$52/('Calcul Re'!$B$46*'Calcul Re'!$B$51) -> 985.9579 | I8: =(0.5961+0.0261*'Calcul Re'!$B$60^2-0.216*'Calcul Re'!$B$60^8+0.000521*(1000000*'Calcul Re'!$B$60/MAX(4*0.1/(PI()*'Calcul Re'!$B$58*'Calcul Re'!$B$46),100))^0.7+(0.0188+0.0063*(19000*'Calcul Re'!$B$60/MAX(4*0.1/(PI()*'Calcul Re'!$B$58*'Calcul Re'!$B$46),100))^0.8)*'Calcul Re'!$B$60^3.5*(1000000/MAX(4*0.1/(PI()*'Calcul Re'!$B$58*'Calcul Re'!$B$46),100))^0.3)*'Calcul Re'!$B$61*(1-(0.41+0.35*'Calcul Re'!$B$60^4)*$A8/('Calcul Re'!$B$17*'Calcul Re'!$B$35))*PI()*'Calcul Re'!$B$59^2/4*SQRT(2*MAX($A8,0)*'Calcul Re'!$B$45) -> 0.0018411423 | J8: =(0.5961+0.0261*'Calcul Re'!$B$60^2-0.216*'Calcul Re'!$B$60^8+0.000521*(1000000*'Calcul Re'!$B$60/MAX(4*I8/(PI()*'Calcul Re'!$B$58*'Calcul Re'!$B$46),100))^0.7+(0.0188+0.0063*(19000*'Calcul Re'!$B$60/MAX(4*I8/(PI()*'Calcul Re'!$B$58*'Calcul Re'!$B$46),100))^0.8)*'Calcul Re'!$B$60^3.5*(1000000/MAX(4*I8/(PI()*'Calcul Re'!$B$58*'Calcul Re'!$B$46),100))^0.3)*'Calcul Re'!$B$61*(1-(0.41+0.35*'Calcul Re'!$B$60^4)*$A8/('Calcul Re'!$B$17*'Calcul Re'!$B$35))*PI()*'Calcul Re'!$B$59^2/4*SQRT(2*MAX($A8,0)*'Calcul Re'!$B$45) -> 0.0020147849 | K8: =(0.5961+0.0261*'Calcul Re'!$B$60^2-0.216*'Calcul Re'!$B$60^8+0.000521*(1000000*'Calcul Re'!$B$60/MAX(4*J8/(PI()*'Calcul Re'!$B$58*'Calcul Re'!$B$46),100))^0.7+(0.0188+0.0063*(19000*'Calcul Re'!$B$60/MAX(4*J8/(PI()*'Calcul Re'!$B$58*'Calcul Re'!$B$46),100))^0.8)*'Calcul Re'!$B$60^3.5*(1000000/MAX(4*J8/(PI()*'Calcul Re'!$B$58*'Calcul Re'!$B$46),100))^0.3)*'Calcul Re'!$B$61*(1-(0.41+0.35*'Calcul Re'!$B$60^4)*$A8/('Calcul Re'!$B$17*'Calcul Re'!$B$35))*PI()*'Calcul Re'!$B$59^2/4*SQRT(2*MAX($A8,0)*'Calcul Re'!$B$45) -> 0.0020024606 | L8: =(0.5961+0.0261*'Calcul Re'!$B$60^2-0.216*'Calcul Re'!$B$60^8+0.000521*(1000000*'Calcul Re'!$B$60/MAX(4*K8/(PI()*'Calcul Re'!$B$58*'Calcul Re'!$B$46),100))^0.7+(0.0188+0.0063*(19000*'Calcul Re'!$B$60/MAX(4*K8/(PI()*'Calcul Re'!$B$58*'Calcul Re'!$B$46),100))^0.8)*'Calcul Re'!$B$60^3.5*(1000000/MAX(4*K8/(PI()*'Calcul Re'!$B$58*'Calcul Re'!$B$46),100))^0.3)*'Calcul Re'!$B$61*(1-(0.41+0.35*'Calcul Re'!$B$60^4)*$A8/('Calcul Re'!$B$17*'Calcul Re'!$B$35))*PI()*'Calcul Re'!$B$59^2/4*SQRT(2*MAX($A8,0)*'Calcul Re'!$B$45) -> 0.0020032701 | M8: =(0.5961+0.0261*'Calcul Re'!$B$60^2-0.216*'Calcul Re'!$B$60^8+0.000521*(1000000*'Calcul Re'!$B$60/MAX(4*L8/(PI()*'Calcul Re'!$B$58*'Calcul Re'!$B$46),100))^0.7+(0.0188+0.0063*(19000*'Calcul Re'!$B$60/MAX(4*L8/(PI()*'Calcul Re'!$B$58*'Calcul Re'!$B$46),100))^0.8)*'Calcul Re'!$B$60^3.5*(1000000/MAX(4*L8/(PI()*'Calcul Re'!$B$58*'Calcul Re'!$B$46),100))^0.3)*'Calcul Re'!$B$61*(1-(0.41+0.35*'Calcul Re'!$B$60^4)*$A8/('Calcul Re'!$B$17*'Calcul Re'!$B$35))*PI()*'Calcul Re'!$B$59^2/4*SQRT(2*MAX($A8,0)*'Calcul Re'!$B$45) -> 0.0020032167 | N8: =(0.5961+0.0261*'Calcul Re'!$B$60^2-0.216*'Calcul Re'!$B$60^8+0.000521*(1000000*'Calcul Re'!$B$60/MAX(4*M8/(PI()*'Calcul Re'!$B$58*'Calcul Re'!$B$46),100))^0.7+(0.0188+0.0063*(19000*'Calcul Re'!$B$60/MAX(4*M8/(PI()*'Calcul Re'!$B$58*'Calcul Re'!$B$46),100))^0.8)*'Calcul Re'!$B$60^3.5*(1000000/MAX(4*M8/(PI()*'Calcul Re'!$B$58*'Calcul Re'!$B$46),100))^0.3)*'Calcul Re'!$B$61*(1-(0.41+0.35*'Calcul Re'!$B$60^4)*$A8/('Calcul Re'!$B$17*'Calcul Re'!$B$35))*PI()*'Calcul Re'!$B$59^2/4*SQRT(2*MAX($A8,0)*'Calcul Re'!$B$45) -> 0.0020032202 | O8: =(0.5961+0.0261*'Calcul Re'!$B$60^2-0.216*'Calcul Re'!$B$60^8+0.000521*(1000000*'Calcul Re'!$B$60/MAX(4*N8/(PI()*'Calcul Re'!$B$58*'Calcul Re'!$B$46),100))^0.7+(0.0188+0.0063*(19000*'Calcul Re'!$B$60/MAX(4*N8/(PI()*'Calcul Re'!$B$58*'Calcul Re'!$B$46),100))^0.8)*'Calcul Re'!$B$60^3.5*(1000000/MAX(4*N8/(PI()*'Calcul Re'!$B$58*'Calcul Re'!$B$46),100))^0.3)*'Calcul Re'!$B$61*(1-(0.41+0.35*'Calcul Re'!$B$60^4)*$A8/('Calcul Re'!$B$17*'Calcul Re'!$B$35))*PI()*'Calcul Re'!$B$59^2/4*SQRT(2*MAX($A8,0)*'Calcul Re'!$B$45) -> 0.00200322 | P8: =(0.5961+0.0261*'Calcul Re'!$B$60^2-0.216*'Calcul Re'!$B$60^8+0.000521*(1000000*'Calcul Re'!$B$60/MAX(4*O8/(PI()*'Calcul Re'!$B$58*'Calcul Re'!$B$46),100))^0.7+(0.0188+0.0063*(19000*'Calcul Re'!$B$60/MAX(4*O8/(PI()*'Calcul Re'!$B$58*'Calcul Re'!$B$46),100))^0.8)*'Calcul Re'!$B$60^3.5*(1000000/MAX(4*O8/(PI()*'Calcul Re'!$B$58*'Calcul Re'!$B$46),100))^0.3)*'Calcul Re'!$B$61*(1-(0.41+0.35*'Calcul Re'!$B$60^4)*$A8/('Calcul Re'!$B$17*'Calcul Re'!$B$35))*PI()*'Calcul Re'!$B$59^2/4*SQRT(2*MAX($A8,0)*'Calcul Re'!$B$45) -> 0.00200322 | Q8: =(0.5961+0.0261*'Calcul Re'!$B$60^2-0.216*'Calcul Re'!$B$60^8+0.000521*(1000000*'Calcul Re'!$B$60/MAX(4*P8/(PI()*'Calcul Re'!$B$58*'Calcul Re'!$B$46),100))^0.7+(0.0188+0.0063*(19000*'Calcul Re'!$B$60/MAX(4*P8/(PI()*'Calcul Re'!$B$58*'Calcul Re'!$B$46),100))^0.8)*'Calcul Re'!$B$60^3.5*(1000000/MAX(4*P8/(PI()*'Calcul Re'!$B$58*'Calcul Re'!$B$46),100))^0.3)*'Calcul Re'!$B$61*(1-(0.41+0.35*'Calcul Re'!$B$60^4)*$A8/('Calcul Re'!$B$17*'Calcul Re'!$B$35))*PI()*'Calcul Re'!$B$59^2/4*SQRT(2*MAX($A8,0)*'Calcul Re'!$B$45) -> 0.00200322 | R8: =(0.5961+0.0261*'Calcul Re'!$B$60^2-0.216*'Calcul Re'!$B$60^8+0.000521*(1000000*'Calcul Re'!$B$60/MAX(4*Q8/(PI()*'Calcul Re'!$B$58*'Calcul Re'!$B$46),100))^0.7+(0.0188+0.0063*(19000*'Calcul Re'!$B$60/MAX(4*Q8/(PI()*'Calcul Re'!$B$58*'Calcul Re'!$B$46),100))^0.8)*'Calcul Re'!$B$60^3.5*(1000000/MAX(4*Q8/(PI()*'Calcul Re'!$B$58*'Calcul Re'!$B$46),100))^0.3)*'Calcul Re'!$B$61*(1-(0.41+0.35*'Calcul Re'!$B$60^4)*$A8/('Calcul Re'!$B$17*'Calcul Re'!$B$35))*PI()*'Calcul Re'!$B$59^2/4*SQRT(2*MAX($A8,0)*'Calcul Re'!$B$45) -> 0.00200322
A9: 3 | B9: =IF($A9<'Calcul Re'!$B$22,0,PI()*SQRT(2)/4*'Calcul Re'!$C$63*'Calcul Re'!$C$59^2*(1-(0.41+0.35*'Calcul Re'!$C$60^4)/'Calcul Re'!$B$17*($A9/'Calcul Re'!$B$35))*SQRT($A9)*SQRT('Calcul Re'!$B$45)/SQRT(1-'Calcul Re'!$C$60^4)) -> 0.00073034491 | C9: =4*B9/(PI()*'Calcul Re'!$B$26/1000*'Calcul Re'!$B$46) -> 672.18932 | D9: =B9*'Calcul Re'!$B$52/('Calcul Re'!$B$46*'Calcul Re'!$B$51) -> 359.46593 | E9: =IF($A9<'Calcul Re'!$B$22,0,R9) -> 0.0024248518 | F9: =4*E9/(PI()*'Calcul Re'!$B$26/1000*'Calcul Re'!$B$46) -> 2231.7668 | G9: =E9*'Calcul Re'!$B$52/('Calcul Re'!$B$46*'Calcul Re'!$B$51) -> 1193.4794 | I9: =(0.5961+0.0261*'Calcul Re'!$B$60^2-0.216*'Calcul Re'!$B$60^8+0.000521*(1000000*'Calcul Re'!$B$60/MAX(4*0.1/(PI()*'Calcul Re'!$B$58*'Calcul Re'!$B$46),100))^0.7+(0.0188+0.0063*(19000*'Calcul Re'!$B$60/MAX(4*0.1/(PI()*'Calcul Re'!$B$58*'Calcul Re'!$B$46),100))^0.8)*'Calcul Re'!$B$60^3.5*(1000000/MAX(4*0.1/(PI()*'Calcul Re'!$B$58*'Calcul Re'!$B$46),100))^0.3)*'Calcul Re'!$B$61*(1-(0.41+0.35*'Calcul Re'!$B$60^4)*$A9/('Calcul Re'!$B$17*'Calcul Re'!$B$35))*PI()*'Calcul Re'!$B$59^2/4*SQRT(2*MAX($A9,0)*'Calcul Re'!$B$45) -> 0.0022549226 | J9: =(0.5961+0.0261*'Calcul Re'!$B$60^2-0.216*'Calcul Re'!$B$60^8+0.000521*(1000000*'Calcul Re'!$B$60/MAX(4*I9/(PI()*'Calcul Re'!$B$58*'Calcul Re'!$B$46),100))^0.7+(0.0188+0.0063*(19000*'Calcul Re'!$B$60/MAX(4*I9/(PI()*'Calcul Re'!$B$58*'Calcul Re'!$B$46),100))^0.8)*'Calcul Re'!$B$60^3.5*(1000000/MAX(4*I9/(PI()*'Calcul Re'!$B$58*'Calcul Re'!$B$46),100))^0.3)*'Calcul Re'!$B$61*(1-(0.41+0.35*'Calcul Re'!$B$60^4)*$A9/('Calcul Re'!$B$17*'Calcul Re'!$B$35))*PI()*'Calcul Re'!$B$59^2/4*SQRT(2*MAX($A9,0)*'Calcul Re'!$B$45) -> 0.0024351841 | K9: =(0.5961+0.0261*'Calcul Re'!$B$60^2-0.216*'Calcul Re'!$B$60^8+0.000521*(1000000*'Calcul Re'!$B$60/MAX(4*J9/(PI()*'Calcul Re'!$B$58*'Calcul Re'!$B$46),100))^0.7+(0.0188+0.0063*(19000*'Calcul Re'!$B$60/MAX(4*J9/(PI()*'Calcul Re'!$B$58*'Calcul Re'!$B$46),100))^0.8)*'Calcul Re'!$B$60^3.5*(1000000/MAX(4*J9/(PI()*'Calcul Re'!$B$58*'Calcul Re'!$B$46),100))^0.3)*'Calcul Re'!$B$61*(1-(0.41+0.35*'Calcul Re'!$B$60^4)*$A9/('Calcul Re'!$B$17*'Calcul Re'!$B$35))*PI()*'Calcul Re'!$B$59^2/4*SQRT(2*MAX($A9,0)*'Calcul Re'!$B$45) -> 0.0024242664 | L9: =(0.5961+0.0261*'Calcul Re'!$B$60^2-0.216*'Calcul Re'!$B$60^8+0.000521*(1000000*'Calcul Re'!$B$60/MAX(4*K9/(PI()*'Calcul Re'!$B$58*'Calcul Re'!$B$46),100))^0.7+(0.0188+0.0063*(19000*'Calcul Re'!$B$60/MAX(4*K9/(PI()*'Calcul Re'!$B$58*'Calcul Re'!$B$46),100))^0.8)*'Calcul Re'!$B$60^3.5*(1000000/MAX(4*K9/(PI()*'Calcul Re'!$B$58*'Calcul Re'!$B$46),100))^0.3)*'Calcul Re'!$B$61*(1-(0.41+0.35*'Calcul Re'!$B$60^4)*$A9/('Calcul Re'!$B$17*'Calcul Re'!$B$35))*PI()*'Calcul Re'!$B$59^2/4*SQRT(2*MAX($A9,0)*'Calcul Re'!$B$45) -> 0.0024248852 | M9: =(0.5961+0.0261*'Calcul Re'!$B$60^2-0.216*'Calcul Re'!$B$60^8+0.000521*(1000000*'Calcul Re'!$B$60/MAX(4*L9/(PI()*'Calcul Re'!$B$58*'Calcul Re'!$B$46),100))^0.7+(0.0188+0.0063*(19000*'Calcul Re'!$B$60/MAX(4*L9/(PI()*'Calcul Re'!$B$58*'Calcul Re'!$B$46),100))^0.8)*'Calcul Re'!$B$60^3.5*(1000000/MAX(4*L9/(PI()*'Calcul Re'!$B$58*'Calcul Re'!$B$46),100))^0.3)*'Calcul Re'!$B$61*(1-(0.41+0.35*'Calcul Re'!$B$60^4)*$A9/('Calcul Re'!$B$17*'Calcul Re'!$B$35))*PI()*'Calcul Re'!$B$59^2/4*SQRT(2*MAX($A9,0)*'Calcul Re'!$B$45) -> 0.0024248499 | N9: =(0.5961+0.0261*'Calcul Re'!$B$60^2-0.216*'Calcul Re'!$B$60^8+0.000521*(1000000*'Calcul Re'!$B$60/MAX(4*M9/(PI()*'Calcul Re'!$B$58*'Calcul Re'!$B$46),100))^0.7+(0.0188+0.0063*(19000*'Calcul Re'!$B$60/MAX(4*M9/(PI()*'Calcul Re'!$B$58*'Calcul Re'!$B$46),100))^0.8)*'Calcul Re'!$B$60^3.5*(1000000/MAX(4*M9/(PI()*'Calcul Re'!$B$58*'Calcul Re'!$B$46),100))^0.3)*'Calcul Re'!$B$61*(1-(0.41+0.35*'Calcul Re'!$B$60^4)*$A9/('Calcul Re'!$B$17*'Calcul Re'!$B$35))*PI()*'Calcul Re'!$B$59^2/4*SQRT(2*MAX($A9,0)*'Calcul Re'!$B$45) -> 0.002424852 | O9: =(0.5961+0.0261*'Calcul Re'!$B$60^2-0.216*'Calcul Re'!$B$60^8+0.000521*(1000000*'Calcul Re'!$B$60/MAX(4*N9/(PI()*'Calcul Re'!$B$58*'Calcul Re'!$B$46),100))^0.7+(0.0188+0.0063*(19000*'Calcul Re'!$B$60/MAX(4*N9/(PI()*'Calcul Re'!$B$58*'Calcul Re'!$B$46),100))^0.8)*'Calcul Re'!$B$60^3.5*(1000000/MAX(4*N9/(PI()*'Calcul Re'!$B$58*'Calcul Re'!$B$46),100))^0.3)*'Calcul Re'!$B$61*(1-(0.41+0.35*'Calcul Re'!$B$60^4)*$A9/('Calcul Re'!$B$17*'Calcul Re'!$B$35))*PI()*'Calcul Re'!$B$59^2/4*SQRT(2*MAX($A9,0)*'Calcul Re'!$B$45) -> 0.0024248518 | P9: =(0.5961+0.0261*'Calcul Re'!$B$60^2-0.216*'Calcul Re'!$B$60^8+0.000521*(1000000*'Calcul Re'!$B$60/MAX(4*O9/(PI()*'Calcul Re'!$B$58*'Calcul Re'!$B$46),100))^0.7+(0.0188+0.0063*(19000*'Calcul Re'!$B$60/MAX(4*O9/(PI()*'Calcul Re'!$B$58*'Calcul Re'!$B$46),100))^0.8)*'Calcul Re'!$B$60^3.5*(1000000/MAX(4*O9/(PI()*'Calcul Re'!$B$58*'Calcul Re'!$B$46),100))^0.3)*'Calcul Re'!$B$61*(1-(0.41+0.35*'Calcul Re'!$B$60^4)*$A9/('Calcul Re'!$B$17*'Calcul Re'!$B$35))*PI()*'Calcul Re'!$B$59^2/4*SQRT(2*MAX($A9,0)*'Calcul Re'!$B$45) -> 0.0024248518 | Q9: =(0.5961+0.0261*'Calcul Re'!$B$60^2-0.216*'Calcul Re'!$B$60^8+0.000521*(1000000*'Calcul Re'!$B$60/MAX(4*P9/(PI()*'Calcul Re'!$B$58*'Calcul Re'!$B$46),100))^0.7+(0.0188+0.0063*(19000*'Calcul Re'!$B$60/MAX(4*P9/(PI()*'Calcul Re'!$B$58*'Calcul Re'!$B$46),100))^0.8)*'Calcul Re'!$B$60^3.5*(1000000/MAX(4*P9/(PI()*'Calcul Re'!$B$58*'Calcul Re'!$B$46),100))^0.3)*'Calcul Re'!$B$61*(1-(0.41+0.35*'Calcul Re'!$B$60^4)*$A9/('Calcul Re'!$B$17*'Calcul Re'!$B$35))*PI()*'Calcul Re'!$B$59^2/4*SQRT(2*MAX($A9,0)*'Calcul Re'!$B$45) -> 0.0024248518 | R9: =(0.5961+0.0261*'Calcul Re'!$B$60^2-0.216*'Calcul Re'!$B$60^8+0.000521*(1000000*'Calcul Re'!$B$60/MAX(4*Q9/(PI()*'Calcul Re'!$B$58*'Calcul Re'!$B$46),100))^0.7+(0.0188+0.0063*(19000*'Calcul Re'!$B$60/MAX(4*Q9/(PI()*'Calcul Re'!$B$58*'Calcul Re'!$B$46),100))^0.8)*'Calcul Re'!$B$60^3.5*(1000000/MAX(4*Q9/(PI()*'Calcul Re'!$B$58*'Calcul Re'!$B$46),100))^0.3)*'Calcul Re'!$B$61*(1-(0.41+0.35*'Calcul Re'!$B$60^4)*$A9/('Calcul Re'!$B$17*'Calcul Re'!$B$35))*PI()*'Calcul Re'!$B$59^2/4*SQRT(2*MAX($A9,0)*'Calcul Re'!$B$45) -> 0.0024248518
A10: 5 | B10: =IF($A10<'Calcul Re'!$B$22,0,PI()*SQRT(2)/4*'Calcul Re'!$C$63*'Calcul Re'!$C$59^2*(1-(0.41+0.35*'Calcul Re'!$C$60^4)/'Calcul Re'!$B$17*($A10/'Calcul Re'!$B$35))*SQRT($A10)*SQRT('Calcul Re'!$B$45)/SQRT(1-'Calcul Re'!$C$60^4)) -> 0.00094286577 | C10: =4*B10/(PI()*'Calcul Re'!$B$26/1000*'Calcul Re'!$B$46) -> 867.78766 | D10: =B10*'Calcul Re'!$B$52/('Calcul Re'!$B$46*'Calcul Re'!$B$51) -> 464.06584 | E10: =IF($A10<'Calcul Re'!$B$22,0,R10) -> 0.003091279 | F10: =4*E10/(PI()*'Calcul Re'!$B$26/1000*'Calcul Re'!$B$46) -> 2845.128 | G10: =E10*'Calcul Re'!$B$52/('Calcul Re'!$B$46*'Calcul Re'!$B$51) -> 1521.4859 | I10: =(0.5961+0.0261*'Calcul Re'!$B$60^2-0.216*'Calcul Re'!$B$60^8+0.000521*(1000000*'Calcul Re'!$B$60/MAX(4*0.1/(PI()*'Calcul Re'!$B$58*'Calcul Re'!$B$46),100))^0.7+(0.0188+0.0063*(19000*'Calcul Re'!$B$60/MAX(4*0.1/(PI()*'Calcul Re'!$B$58*'Calcul Re'!$B$46),100))^0.8)*'Calcul Re'!$B$60^3.5*(1000000/MAX(4*0.1/(PI()*'Calcul Re'!$B$58*'Calcul Re'!$B$46),100))^0.3)*'Calcul Re'!$B$61*(1-(0.41+0.35*'Calcul Re'!$B$60^4)*$A10/('Calcul Re'!$B$17*'Calcul Re'!$B$35))*PI()*'Calcul Re'!$B$59^2/4*SQRT(2*MAX($A10,0)*'Calcul Re'!$B$45) -> 0.0029110747 | J10: =(0.5961+0.0261*'Calcul Re'!$B$60^2-0.216*'Calcul Re'!$B$60^8+0.000521*(1000000*'Calcul Re'!$B$60/MAX(4*I10/(PI()*'Calcul Re'!$B$58*'Calcul Re'!$B$46),100))^0.7+(0.0188+0.0063*(19000*'Calcul Re'!$B$60/MAX(4*I10/(PI()*'Calcul Re'!$B$58*'Calcul Re'!$B$46),100))^0.8)*'Calcul Re'!$B$60^3.5*(1000000/MAX(4*I10/(PI()*'Calcul Re'!$B$58*'Calcul Re'!$B$46),100))^0.3)*'Calcul Re'!$B$61*(1-(0.41+0.35*'Calcul Re'!$B$60^4)*$A10/('Calcul Re'!$B$17*'Calcul Re'!$B$35))*PI()*'Calcul Re'!$B$59^2/4*SQRT(2*MAX($A10,0)*'Calcul Re'!$B$45) -> 0.0031002523 | K10: =(0.5961+0.0261*'Calcul Re'!$B$60^2-0.216*'Calcul Re'!$B$60^8+0.000521*(1000000*'Calcul Re'!$B$60/MAX(4*J10/(PI()*'Calcul Re'!$B$58*'Calcul Re'!$B$46),100))^0.7+(0.0188+0.0063*(19000*'Calcul Re'!$B$60/MAX(4*J10/(PI()*'Calcul Re'!$B$58*'Calcul Re'!$B$46),100))^0.8)*'Calcul Re'!$B$60^3.5*(1000000/MAX(4*J10/(PI()*'Calcul Re'!$B$58*'Calcul Re'!$B$46),100))^0.3)*'Calcul Re'!$B$61*(1-(0.41+0.35*'Calcul Re'!$B$60^4)*$A10/('Calcul Re'!$B$17*'Calcul Re'!$B$35))*PI()*'Calcul Re'!$B$59^2/4*SQRT(2*MAX($A10,0)*'Calcul Re'!$B$45) -> 0.003090857 | L10: =(0.5961+0.0261*'Calcul Re'!$B$60^2-0.216*'Calcul Re'!$B$60^8+0.000521*(1000000*'Calcul Re'!$B$60/MAX(4*K10/(PI()*'Calcul Re'!$B$58*'Calcul Re'!$B$46),100))^0.7+(0.0188+0.0063*(19000*'Calcul Re'!$B$60/MAX(4*K10/(PI()*'Calcul Re'!$B$58*'Calcul Re'!$B$46),100))^0.8)*'Calcul Re'!$B$60^3.5*(1000000/MAX(4*K10/(PI()*'Calcul Re'!$B$58*'Calcul Re'!$B$46),100))^0.3)*'Calcul Re'!$B$61*(1-(0.41+0.35*'Calcul Re'!$B$60^4)*$A10/('Calcul Re'!$B$17*'Calcul Re'!$B$35))*PI()*'Calcul Re'!$B$59^2/4*SQRT(2*MAX($A10,0)*'Calcul Re'!$B$45) -> 0.0030912989 | M10: =(0.5961+0.0261*'Calcul Re'!$B$60^2-0.216*'Calcul Re'!$B$60^8+0.000521*(1000000*'Calcul Re'!$B$60/MAX(4*L10/(PI()*'Calcul Re'!$B$58*'Calcul Re'!$B$46),100))^0.7+(0.0188+0.0063*(19000*'Calcul Re'!$B$60/MAX(4*L10/(PI()*'Calcul Re'!$B$58*'Calcul Re'!$B$46),100))^0.8)*'Calcul Re'!$B$60^3.5*(1000000/MAX(4*L10/(PI()*'Calcul Re'!$B$58*'Calcul Re'!$B$46),100))^0.3)*'Calcul Re'!$B$61*(1-(0.41+0.35*'Calcul Re'!$B$60^4)*$A10/('Calcul Re'!$B$17*'Calcul Re'!$B$35))*PI()*'Calcul Re'!$B$59^2/4*SQRT(2*MAX($A10,0)*'Calcul Re'!$B$45) -> 0.0030912781 | N10: =(0.5961+0.0261*'Calcul Re'!$B$60^2-0.216*'Calcul Re'!$B$60^8+0.000521*(1000000*'Calcul Re'!$B$60/MAX(4*M10/(PI()*'Calcul Re'!$B$58*'Calcul Re'!$B$46),100))^0.7+(0.0188+0.0063*(19000*'Calcul Re'!$B$60/MAX(4*M10/(PI()*'Calcul Re'!$B$58*'Calcul Re'!$B$46),100))^0.8)*'Calcul Re'!$B$60^3.5*(1000000/MAX(4*M10/(PI()*'Calcul Re'!$B$58*'Calcul Re'!$B$46),100))^0.3)*'Calcul Re'!$B$61*(1-(0.41+0.35*'Calcul Re'!$B$60^4)*$A10/('Calcul Re'!$B$17*'Calcul Re'!$B$35))*PI()*'Calcul Re'!$B$59^2/4*SQRT(2*MAX($A10,0)*'Calcul Re'!$B$45) -> 0.0030912791 | O10: =(0.5961+0.0261*'Calcul Re'!$B$60^2-0.216*'Calcul Re'!$B$60^8+0.000521*(1000000*'Calcul Re'!$B$60/MAX(4*N10/(PI()*'Calcul Re'!$B$58*'Calcul Re'!$B$46),100))^0.7+(0.0188+0.0063*(19000*'Calcul Re'!$B$60/MAX(4*N10/(PI()*'Calcul Re'!$B$58*'Calcul Re'!$B$46),100))^0.8)*'Calcul Re'!$B$60^3.5*(1000000/MAX(4*N10/(PI()*'Calcul Re'!$B$58*'Calcul Re'!$B$46),100))^0.3)*'Calcul Re'!$B$61*(1-(0.41+0.35*'Calcul Re'!$B$60^4)*$A10/('Calcul Re'!$B$17*'Calcul Re'!$B$35))*PI()*'Calcul Re'!$B$59^2/4*SQRT(2*MAX($A10,0)*'Calcul Re'!$B$45) -> 0.003091279 | P10: =(0.5961+0.0261*'Calcul Re'!$B$60^2-0.216*'Calcul Re'!$B$60^8+0.000521*(1000000*'Calcul Re'!$B$60/MAX(4*O10/(PI()*'Calcul Re'!$B$58*'Calcul Re'!$B$46),100))^0.7+(0.0188+0.0063*(19000*'Calcul Re'!$B$60/MAX(4*O10/(PI()*'Calcul Re'!$B$58*'Calcul Re'!$B$46),100))^0.8)*'Calcul Re'!$B$60^3.5*(1000000/MAX(4*O10/(PI()*'Calcul Re'!$B$58*'Calcul Re'!$B$46),100))^0.3)*'Calcul Re'!$B$61*(1-(0.41+0.35*'Calcul Re'!$B$60^4)*$A10/('Calcul Re'!$B$17*'Calcul Re'!$B$35))*PI()*'Calcul Re'!$B$59^2/4*SQRT(2*MAX($A10,0)*'Calcul Re'!$B$45) -> 0.003091279 | Q10: =(0.5961+0.0261*'Calcul Re'!$B$60^2-0.216*'Calcul Re'!$B$60^8+0.000521*(1000000*'Calcul Re'!$B$60/MAX(4*P10/(PI()*'Calcul Re'!$B$58*'Calcul Re'!$B$46),100))^0.7+(0.0188+0.0063*(19000*'Calcul Re'!$B$60/MAX(4*P10/(PI()*'Calcul Re'!$B$58*'Calcul Re'!$B$46),100))^0.8)*'Calcul Re'!$B$60^3.5*(1000000/MAX(4*P10/(PI()*'Calcul Re'!$B$58*'Calcul Re'!$B$46),100))^0.3)*'Calcul Re'!$B$61*(1-(0.41+0.35*'Calcul Re'!$B$60^4)*$A10/('Calcul Re'!$B$17*'Calcul Re'!$B$35))*PI()*'Calcul Re'!$B$59^2/4*SQRT(2*MAX($A10,0)*'Calcul Re'!$B$45) -> 0.003091279 | R10: =(0.5961+0.0261*'Calcul Re'!$B$60^2-0.216*'Calcul Re'!$B$60^8+0.000521*(1000000*'Calcul Re'!$B$60/MAX(4*Q10/(PI()*'Calcul Re'!$B$58*'Calcul Re'!$B$46),100))^0.7+(0.0188+0.0063*(19000*'Calcul Re'!$B$60/MAX(4*Q10/(PI()*'Calcul Re'!$B$58*'Calcul Re'!$B$46),100))^0.8)*'Calcul Re'!$B$60^3.5*(1000000/MAX(4*Q10/(PI()*'Calcul Re'!$B$58*'Calcul Re'!$B$46),100))^0.3)*'Calcul Re'!$B$61*(1-(0.41+0.35*'Calcul Re'!$B$60^4)*$A10/('Calcul Re'!$B$17*'Calcul Re'!$B$35))*PI()*'Calcul Re'!$B$59^2/4*SQRT(2*MAX($A10,0)*'Calcul Re'!$B$45) -> 0.003091279
A11: 7.5 | B11: =IF($A11<'Calcul Re'!$B$22,0,PI()*SQRT(2)/4*'Calcul Re'!$C$63*'Calcul Re'!$C$59^2*(1-(0.41+0.35*'Calcul Re'!$C$60^4)/'Calcul Re'!$B$17*($A11/'Calcul Re'!$B$35))*SQRT($A11)*SQRT('Calcul Re'!$B$45)/SQRT(1-'Calcul Re'!$C$60^4)) -> 0.0011547617 | C11: =4*B11/(PI()*'Calcul Re'!$B$26/1000*'Calcul Re'!$B$46) -> 1062.8108 | D11: =B11*'Calcul Re'!$B$52/('Calcul Re'!$B$46*'Calcul Re'!$B$51) -> 568.35815 | E11: =IF($A11<'Calcul Re'!$B$22,0,R11) -> 0.0037539224 | F11: =4*E11/(PI()*'Calcul Re'!$B$26/1000*'Calcul Re'!$B$46) -> 3455.0067 | G11: =E11*'Calcul Re'!$B$52/('Calcul Re'!$B$46*'Calcul Re'!$B$51) -> 1847.6301 | I11: =(0.5961+0.0261*'Calcul Re'!$B$60^2-0.216*'Calcul Re'!$B$60^8+0.000521*(1000000*'Calcul Re'!$B$60/MAX(4*0.1/(PI()*'Calcul Re'!$B$58*'Calcul Re'!$B$46),100))^0.7+(0.0188+0.0063*(19000*'Calcul Re'!$B$60/MAX(4*0.1/(PI()*'Calcul Re'!$B$58*'Calcul Re'!$B$46),100))^0.8)*'Calcul Re'!$B$60^3.5*(1000000/MAX(4*0.1/(PI()*'Calcul Re'!$B$58*'Calcul Re'!$B$46),100))^0.3)*'Calcul Re'!$B$61*(1-(0.41+0.35*'Calcul Re'!$B$60^4)*$A11/('Calcul Re'!$B$17*'Calcul Re'!$B$35))*PI()*'Calcul Re'!$B$59^2/4*SQRT(2*MAX($A11,0)*'Calcul Re'!$B$45) -> 0.0035652963 | J11: =(0.5961+0.0261*'Calcul Re'!$B$60^2-0.216*'Calcul Re'!$B$60^8+0.000521*(1000000*'Calcul Re'!$B$60/MAX(4*I11/(PI()*'Calcul Re'!$B$58*'Calcul Re'!$B$46),100))^0.7+(0.0188+0.0063*(19000*'Calcul Re'!$B$60/MAX(4*I11/(PI()*'Calcul Re'!$B$58*'Calcul Re'!$B$46),100))^0.8)*'Calcul Re'!$B$60^3.5*(1000000/MAX(4*I11/(PI()*'Calcul Re'!$B$58*'Calcul Re'!$B$46),100))^0.3)*'Calcul Re'!$B$61*(1-(0.41+0.35*'Calcul Re'!$B$60^4)*$A11/('Calcul Re'!$B$17*'Calcul Re'!$B$35))*PI()*'Calcul Re'!$B$59^2/4*SQRT(2*MAX($A11,0)*'Calcul Re'!$B$45) -> 0.0037619524 | K11: =(0.5961+0.0261*'Calcul Re'!$B$60^2-0.216*'Calcul Re'!$B$60^8+0.000521*(1000000*'Calcul Re'!$B$60/MAX(4*J11/(PI()*'Calcul Re'!$B$58*'Calcul Re'!$B$46),100))^0.7+(0.0188+0.0063*(19000*'Calcul Re'!$B$60/MAX(4*J11/(PI()*'Calcul Re'!$B$58*'Calcul Re'!$B$46),100))^0.8)*'Calcul Re'!$B$60^3.5*(1000000/MAX(4*J11/(PI()*'Calcul Re'!$B$58*'Calcul Re'!$B$46),100))^0.3)*'Calcul Re'!$B$61*(1-(0.41+0.35*'Calcul Re'!$B$60^4)*$A11/('Calcul Re'!$B$17*'Calcul Re'!$B$35))*PI()*'Calcul Re'!$B$59^2/4*SQRT(2*MAX($A11,0)*'Calcul Re'!$B$45) -> 0.0037535967 | L11: =(0.5961+0.0261*'Calcul Re'!$B$60^2-0.216*'Calcul Re'!$B$60^8+0.000521*(1000000*'Calcul Re'!$B$60/MAX(4*K11/(PI()*'Calcul Re'!$B$58*'Calcul Re'!$B$46),100))^0.7+(0.0188+0.0063*(19000*'Calcul Re'!$B$60/MAX(4*K11/(PI()*'Calcul Re'!$B$58*'Calcul Re'!$B$46),100))^0.8)*'Calcul Re'!$B$60^3.5*(1000000/MAX(4*K11/(PI()*'Calcul Re'!$B$58*'Calcul Re'!$B$46),100))^0.3)*'Calcul Re'!$B$61*(1-(0.41+0.35*'Calcul Re'!$B$60^4)*$A11/('Calcul Re'!$B$17*'Calcul Re'!$B$35))*PI()*'Calcul Re'!$B$59^2/4*SQRT(2*MAX($A11,0)*'Calcul Re'!$B$45) -> 0.0037539356 | M11: =(0.5961+0.0261*'Calcul Re'!$B$60^2-0.216*'Calcul Re'!$B$60^8+0.000521*(1000000*'Calcul Re'!$B$60/MAX(4*L11/(PI()*'Calcul Re'!$B$58*'Calcul Re'!$B$46),100))^0.7+(0.0188+0.0063*(19000*'Calcul Re'!$B$60/MAX(4*L11/(PI()*'Calcul Re'!$B$58*'Calcul Re'!$B$46),100))^0.8)*'Calcul Re'!$B$60^3.5*(1000000/MAX(4*L11/(PI()*'Calcul Re'!$B$58*'Calcul Re'!$B$46),100))^0.3)*'Calcul Re'!$B$61*(1-(0.41+0.35*'Calcul Re'!$B$60^4)*$A11/('Calcul Re'!$B$17*'Calcul Re'!$B$35))*PI()*'Calcul Re'!$B$59^2/4*SQRT(2*MAX($A11,0)*'Calcul Re'!$B$45) -> 0.0037539218 | N11: =(0.5961+0.0261*'Calcul Re'!$B$60^2-0.216*'Calcul Re'!$B$60^8+0.000521*(1000000*'Calcul Re'!$B$60/MAX(4*M11/(PI()*'Calcul Re'!$B$58*'Calcul Re'!$B$46),100))^0.7+(0.0188+0.0063*(19000*'Calcul Re'!$B$60/MAX(4*M11/(PI()*'Calcul Re'!$B$58*'Calcul Re'!$B$46),100))^0.8)*'Calcul Re'!$B$60^3.5*(1000000/MAX(4*M11/(PI()*'Calcul Re'!$B$58*'Calcul Re'!$B$46),100))^0.3)*'Calcul Re'!$B$61*(1-(0.41+0.35*'Calcul Re'!$B$60^4)*$A11/('Calcul Re'!$B$17*'Calcul Re'!$B$35))*PI()*'Calcul Re'!$B$59^2/4*SQRT(2*MAX($A11,0)*'Calcul Re'!$B$45) -> 0.0037539224 | O11: =(0.5961+0.0261*'Calcul Re'!$B$60^2-0.216*'Calcul Re'!$B$60^8+0.000521*(1000000*'Calcul Re'!$B$60/MAX(4*N11/(PI()*'Calcul Re'!$B$58*'Calcul Re'!$B$46),100))^0.7+(0.0188+0.0063*(19000*'Calcul Re'!$B$60/MAX(4*N11/(PI()*'Calcul Re'!$B$58*'Calcul Re'!$B$46),100))^0.8)*'Calcul Re'!$B$60^3.5*(1000000/MAX(4*N11/(PI()*'Calcul Re'!$B$58*'Calcul Re'!$B$46),100))^0.3)*'Calcul Re'!$B$61*(1-(0.41+0.35*'Calcul Re'!$B$60^4)*$A11/('Calcul Re'!$B$17*'Calcul Re'!$B$35))*PI()*'Calcul Re'!$B$59^2/4*SQRT(2*MAX($A11,0)*'Calcul Re'!$B$45) -> 0.0037539224 | P11: =(0.5961+0.0261*'Calcul Re'!$B$60^2-0.216*'Calcul Re'!$B$60^8+0.000521*(1000000*'Calcul Re'!$B$60/MAX(4*O11/(PI()*'Calcul Re'!$B$58*'Calcul Re'!$B$46),100))^0.7+(0.0188+0.0063*(19000*'Calcul Re'!$B$60/MAX(4*O11/(PI()*'Calcul Re'!$B$58*'Calcul Re'!$B$46),100))^0.8)*'Calcul Re'!$B$60^3.5*(1000000/MAX(4*O11/(PI()*'Calcul Re'!$B$58*'Calcul Re'!$B$46),100))^0.3)*'Calcul Re'!$B$61*(1-(0.41+0.35*'Calcul Re'!$B$60^4)*$A11/('Calcul Re'!$B$17*'Calcul Re'!$B$35))*PI()*'Calcul Re'!$B$59^2/4*SQRT(2*MAX($A11,0)*'Calcul Re'!$B$45) -> 0.0037539224 | Q11: =(0.5961+0.0261*'Calcul Re'!$B$60^2-0.216*'Calcul Re'!$B$60^8+0.000521*(1000000*'Calcul Re'!$B$60/MAX(4*P11/(PI()*'Calcul Re'!$B$58*'Calcul Re'!$B$46),100))^0.7+(0.0188+0.0063*(19000*'Calcul Re'!$B$60/MAX(4*P11/(PI()*'Calcul Re'!$B$58*'Calcul Re'!$B$46),100))^0.8)*'Calcul Re'!$B$60^3.5*(1000000/MAX(4*P11/(PI()*'Calcul Re'!$B$58*'Calcul Re'!$B$46),100))^0.3)*'Calcul Re'!$B$61*(1-(0.41+0.35*'Calcul Re'!$B$60^4)*$A11/('Calcul Re'!$B$17*'Calcul Re'!$B$35))*PI()*'Calcul Re'!$B$59^2/4*SQRT(2*MAX($A11,0)*'Calcul Re'!$B$45) -> 0.0037539224 | R11: =(0.5961+0.0261*'Calcul Re'!$B$60^2-0.216*'Calcul Re'!$B$60^8+0.000521*(1000000*'Calcul Re'!$B$60/MAX(4*Q11/(PI()*'Calcul Re'!$B$58*'Calcul Re'!$B$46),100))^0.7+(0.0188+0.0063*(19000*'Calcul Re'!$B$60/MAX(4*Q11/(PI()*'Calcul Re'!$B$58*'Calcul Re'!$B$46),100))^0.8)*'Calcul Re'!$B$60^3.5*(1000000/MAX(4*Q11/(PI()*'Calcul Re'!$B$58*'Calcul Re'!$B$46),100))^0.3)*'Calcul Re'!$B$61*(1-(0.41+0.35*'Calcul Re'!$B$60^4)*$A11/('Calcul Re'!$B$17*'Calcul Re'!$B$35))*PI()*'Calcul Re'!$B$59^2/4*SQRT(2*MAX($A11,0)*'Calcul Re'!$B$45) -> 0.0037539224
A12: 10 | B12: =IF($A12<'Calcul Re'!$B$22,0,PI()*SQRT(2)/4*'Calcul Re'!$C$63*'Calcul Re'!$C$59^2*(1-(0.41+0.35*'Calcul Re'!$C$60^4)/'Calcul Re'!$B$17*($A12/'Calcul Re'!$B$35))*SQRT($A12)*SQRT('Calcul Re'!$B$45)/SQRT(1-'Calcul Re'!$C$60^4)) -> 0.0013333943 | C12: =4*B12/(PI()*'Calcul Re'!$B$26/1000*'Calcul Re'!$B$46) -> 1227.2193 | D12: =B12*'Calcul Re'!$B$52/('Calcul Re'!$B$46*'Calcul Re'!$B$51) -> 656.27872 | E12: =IF($A12<'Calcul Re'!$B$22,0,R12) -> 0.0043115278 | F12: =4*E12/(PI()*'Calcul Re'!$B$26/1000*'Calcul Re'!$B$46) -> 3968.2114 | G12: =E12*'Calcul Re'!$B$52/('Calcul Re'!$B$46*'Calcul Re'!$B$51) -> 2122.076 | I12: =(0.5961+0.0261*'Calcul Re'!$B$60^2-0.216*'Calcul Re'!$B$60^8+0.000521*(1000000*'Calcul Re'!$B$60/MAX(4*0.1/(PI()*'Calcul Re'!$B$58*'Calcul Re'!$B$46),100))^0.7+(0.0188+0.0063*(19000*'Calcul Re'!$B$60/MAX(4*0.1/(PI()*'Calcul Re'!$B$58*'Calcul Re'!$B$46),100))^0.8)*'Calcul Re'!$B$60^3.5*(1000000/MAX(4*0.1/(PI()*'Calcul Re'!$B$58*'Calcul Re'!$B$46),100))^0.3)*'Calcul Re'!$B$61*(1-(0.41+0.35*'Calcul Re'!$B$60^4)*$A12/('Calcul Re'!$B$17*'Calcul Re'!$B$35))*PI()*'Calcul Re'!$B$59^2/4*SQRT(2*MAX($A12,0)*'Calcul Re'!$B$45) -> 0.0041168179 | J12: =(0.5961+0.0261*'Calcul Re'!$B$60^2-0.216*'Calcul Re'!$B$60^8+0.000521*(1000000*'Calcul Re'!$B$60/MAX(4*I12/(PI()*'Calcul Re'!$B$58*'Calcul Re'!$B$46),100))^0.7+(0.0188+0.0063*(19000*'Calcul Re'!$B$60/MAX(4*I12/(PI()*'Calcul Re'!$B$58*'Calcul Re'!$B$46),100))^0.8)*'Calcul Re'!$B$60^3.5*(1000000/MAX(4*I12/(PI()*'Calcul Re'!$B$58*'Calcul Re'!$B$46),100))^0.3)*'Calcul Re'!$B$61*(1-(0.41+0.35*'Calcul Re'!$B$60^4)*$A12/('Calcul Re'!$B$17*'Calcul Re'!$B$35))*PI()*'Calcul Re'!$B$59^2/4*SQRT(2*MAX($A12,0)*'Calcul Re'!$B$45) -> 0.0043189528 | K12: =(0.5961+0.0261*'Calcul Re'!$B$60^2-0.216*'Calcul Re'!$B$60^8+0.000521*(1000000*'Calcul Re'!$B$60/MAX(4*J12/(PI()*'Calcul Re'!$B$58*'Calcul Re'!$B$46),100))^0.7+(0.0188+0.0063*(19000*'Calcul Re'!$B$60/MAX(4*J12/(PI()*'Calcul Re'!$B$58*'Calcul Re'!$B$46),100))^0.8)*'Calcul Re'!$B$60^3.5*(1000000/MAX(4*J12/(PI()*'Calcul Re'!$B$58*'Calcul Re'!$B$46),100))^0.3)*'Calcul Re'!$B$61*(1-(0.41+0.35*'Calcul Re'!$B$60^4)*$A12/('Calcul Re'!$B$17*'Calcul Re'!$B$35))*PI()*'Calcul Re'!$B$59^2/4*SQRT(2*MAX($A12,0)*'Calcul Re'!$B$45) -> 0.0043112566 | L12: =(0.5961+0.0261*'Calcul Re'!$B$60^2-0.216*'Calcul Re'!$B$60^8+0.000521*(1000000*'Calcul Re'!$B$60/MAX(4*K12/(PI()*'Calcul Re'!$B$58*'Calcul Re'!$B$46),100))^0.7+(0.0188+0.0063*(19000*'Calcul Re'!$B$60/MAX(4*K12/(PI()*'Calcul Re'!$B$58*'Calcul Re'!$B$46),100))^0.8)*'Calcul Re'!$B$60^3.5*(1000000/MAX(4*K12/(PI()*'Calcul Re'!$B$58*'Calcul Re'!$B$46),100))^0.3)*'Calcul Re'!$B$61*(1-(0.41+0.35*'Calcul Re'!$B$60^4)*$A12/('Calcul Re'!$B$17*'Calcul Re'!$B$35))*PI()*'Calcul Re'!$B$59^2/4*SQRT(2*MAX($A12,0)*'Calcul Re'!$B$45) -> 0.0043115378 | M12: =(0.5961+0.0261*'Calcul Re'!$B$60^2-0.216*'Calcul Re'!$B$60^8+0.000521*(1000000*'Calcul Re'!$B$60/MAX(4*L12/(PI()*'Calcul Re'!$B$58*'Calcul Re'!$B$46),100))^0.7+(0.0188+0.0063*(19000*'Calcul Re'!$B$60/MAX(4*L12/(PI()*'Calcul Re'!$B$58*'Calcul Re'!$B$46),100))^0.8)*'Calcul Re'!$B$60^3.5*(1000000/MAX(4*L12/(PI()*'Calcul Re'!$B$58*'Calcul Re'!$B$46),100))^0.3)*'Calcul Re'!$B$61*(1-(0.41+0.35*'Calcul Re'!$B$60^4)*$A12/('Calcul Re'!$B$17*'Calcul Re'!$B$35))*PI()*'Calcul Re'!$B$59^2/4*SQRT(2*MAX($A12,0)*'Calcul Re'!$B$45) -> 0.0043115275 | N12: =(0.5961+0.0261*'Calcul Re'!$B$60^2-0.216*'Calcul Re'!$B$60^8+0.000521*(1000000*'Calcul Re'!$B$60/MAX(4*M12/(PI()*'Calcul Re'!$B$58*'Calcul Re'!$B$46),100))^0.7+(0.0188+0.0063*(19000*'Calcul Re'!$B$60/MAX(4*M12/(PI()*'Calcul Re'!$B$58*'Calcul Re'!$B$46),100))^0.8)*'Calcul Re'!$B$60^3.5*(1000000/MAX(4*M12/(PI()*'Calcul Re'!$B$58*'Calcul Re'!$B$46),100))^0.3)*'Calcul Re'!$B$61*(1-(0.41+0.35*'Calcul Re'!$B$60^4)*$A12/('Calcul Re'!$B$17*'Calcul Re'!$B$35))*PI()*'Calcul Re'!$B$59^2/4*SQRT(2*MAX($A12,0)*'Calcul Re'!$B$45) -> 0.0043115278 | O12: =(0.5961+0.0261*'Calcul Re'!$B$60^2-0.216*'Calcul Re'!$B$60^8+0.000521*(1000000*'Calcul Re'!$B$60/MAX(4*N12/(PI()*'Calcul Re'!$B$58*'Calcul Re'!$B$46),100))^0.7+(0.0188+0.0063*(19000*'Calcul Re'!$B$60/MAX(4*N12/(PI()*'Calcul Re'!$B$58*'Calcul Re'!$B$46),100))^0.8)*'Calcul Re'!$B$60^3.5*(1000000/MAX(4*N12/(PI()*'Calcul Re'!$B$58*'Calcul Re'!$B$46),100))^0.3)*'Calcul Re'!$B$61*(1-(0.41+0.35*'Calcul Re'!$B$60^4)*$A12/('Calcul Re'!$B$17*'Calcul Re'!$B$35))*PI()*'Calcul Re'!$B$59^2/4*SQRT(2*MAX($A12,0)*'Calcul Re'!$B$45) -> 0.0043115278 | P12: =(0.5961+0.0261*'Calcul Re'!$B$60^2-0.216*'Calcul Re'!$B$60^8+0.000521*(1000000*'Calcul Re'!$B$60/MAX(4*O12/(PI()*'Calcul Re'!$B$58*'Calcul Re'!$B$46),100))^0.7+(0.0188+0.0063*(19000*'Calcul Re'!$B$60/MAX(4*O12/(PI()*'Calcul Re'!$B$58*'Calcul Re'!$B$46),100))^0.8)*'Calcul Re'!$B$60^3.5*(1000000/MAX(4*O12/(PI()*'Calcul Re'!$B$58*'Calcul Re'!$B$46),100))^0.3)*'Calcul Re'!$B$61*(1-(0.41+0.35*'Calcul Re'!$B$60^4)*$A12/('Calcul Re'!$B$17*'Calcul Re'!$B$35))*PI()*'Calcul Re'!$B$59^2/4*SQRT(2*MAX($A12,0)*'Calcul Re'!$B$45) -> 0.0043115278 | Q12: =(0.5961+0.0261*'Calcul Re'!$B$60^2-0.216*'Calcul Re'!$B$60^8+0.000521*(1000000*'Calcul Re'!$B$60/MAX(4*P12/(PI()*'Calcul Re'!$B$58*'Calcul Re'!$B$46),100))^0.7+(0.0188+0.0063*(19000*'Calcul Re'!$B$60/MAX(4*P12/(PI()*'Calcul Re'!$B$58*'Calcul Re'!$B$46),100))^0.8)*'Calcul Re'!$B$60^3.5*(1000000/MAX(4*P12/(PI()*'Calcul Re'!$B$58*'Calcul Re'!$B$46),100))^0.3)*'Calcul Re'!$B$61*(1-(0.41+0.35*'Calcul Re'!$B$60^4)*$A12/('Calcul Re'!$B$17*'Calcul Re'!$B$35))*PI()*'Calcul Re'!$B$59^2/4*SQRT(2*MAX($A12,0)*'Calcul Re'!$B$45) -> 0.0043115278 | R12: =(0.5961+0.0261*'Calcul Re'!$B$60^2-0.216*'Calcul Re'!$B$60^8+0.000521*(1000000*'Calcul Re'!$B$60/MAX(4*Q12/(PI()*'Calcul Re'!$B$58*'Calcul Re'!$B$46),100))^0.7+(0.0188+0.0063*(19000*'Calcul Re'!$B$60/MAX(4*Q12/(PI()*'Calcul Re'!$B$58*'Calcul Re'!$B$46),100))^0.8)*'Calcul Re'!$B$60^3.5*(1000000/MAX(4*Q12/(PI()*'Calcul Re'!$B$58*'Calcul Re'!$B$46),100))^0.3)*'Calcul Re'!$B$61*(1-(0.41+0.35*'Calcul Re'!$B$60^4)*$A12/('Calcul Re'!$B$17*'Calcul Re'!$B$35))*PI()*'Calcul Re'!$B$59^2/4*SQRT(2*MAX($A12,0)*'Calcul Re'!$B$45) -> 0.0043115278
A13: 15 | B13: =IF($A13<'Calcul Re'!$B$22,0,PI()*SQRT(2)/4*'Calcul Re'!$C$63*'Calcul Re'!$C$59^2*(1-(0.41+0.35*'Calcul Re'!$C$60^4)/'Calcul Re'!$B$17*($A13/'Calcul Re'!$B$35))*SQRT($A13)*SQRT('Calcul Re'!$B$45)/SQRT(1-'Calcul Re'!$C$60^4)) -> 0.0016330442 | C13: =4*B13/(PI()*'Calcul Re'!$B$26/1000*'Calcul Re'!$B$46) -> 1503.0089 | D13: =B13*'Calcul Re'!$B$52/('Calcul Re'!$B$46*'Calcul Re'!$B$51) -> 803.76238 | E13: =IF($A13<'Calcul Re'!$B$22,0,R13) -> 0.0052453425 | F13: =4*E13/(PI()*'Calcul Re'!$B$26/1000*'Calcul Re'!$B$46) -> 4827.6686 | G13: =E13*'Calcul Re'!$B$52/('Calcul Re'!$B$46*'Calcul Re'!$B$51) -> 2581.6869 | I13: =(0.5961+0.0261*'Calcul Re'!$B$60^2-0.216*'Calcul Re'!$B$60^8+0.000521*(1000000*'Calcul Re'!$B$60/MAX(4*0.1/(PI()*'Calcul Re'!$B$58*'Calcul Re'!$B$46),100))^0.7+(0.0188+0.0063*(19000*'Calcul Re'!$B$60/MAX(4*0.1/(PI()*'Calcul Re'!$B$58*'Calcul Re'!$B$46),100))^0.8)*'Calcul Re'!$B$60^3.5*(1000000/MAX(4*0.1/(PI()*'Calcul Re'!$B$58*'Calcul Re'!$B$46),100))^0.3)*'Calcul Re'!$B$61*(1-(0.41+0.35*'Calcul Re'!$B$60^4)*$A13/('Calcul Re'!$B$17*'Calcul Re'!$B$35))*PI()*'Calcul Re'!$B$59^2/4*SQRT(2*MAX($A13,0)*'Calcul Re'!$B$45) -> 0.005041974 | J13: =(0.5961+0.0261*'Calcul Re'!$B$60^2-0.216*'Calcul Re'!$B$60^8+0.000521*(1000000*'Calcul Re'!$B$60/MAX(4*I13/(PI()*'Calcul Re'!$B$58*'Calcul Re'!$B$46),100))^0.7+(0.0188+0.0063*(19000*'Calcul Re'!$B$60/MAX(4*I13/(PI()*'Calcul Re'!$B$58*'Calcul Re'!$B$46),100))^0.8)*'Calcul Re'!$B$60^3.5*(1000000/MAX(4*I13/(PI()*'Calcul Re'!$B$58*'Calcul Re'!$B$46),100))^0.3)*'Calcul Re'!$B$61*(1-(0.41+0.35*'Calcul Re'!$B$60^4)*$A13/('Calcul Re'!$B$17*'Calcul Re'!$B$35))*PI()*'Calcul Re'!$B$59^2/4*SQRT(2*MAX($A13,0)*'Calcul Re'!$B$45) -> 0.0052519946 | K13: =(0.5961+0.0261*'Calcul Re'!$B$60^2-0.216*'Calcul Re'!$B$60^8+0.000521*(1000000*'Calcul Re'!$B$60/MAX(4*J13/(PI()*'Calcul Re'!$B$58*'Calcul Re'!$B$46),100))^0.7+(0.0188+0.0063*(19000*'Calcul Re'!$B$60/MAX(4*J13/(PI()*'Calcul Re'!$B$58*'Calcul Re'!$B$46),100))^0.8)*'Calcul Re'!$B$60^3.5*(1000000/MAX(4*J13/(PI()*'Calcul Re'!$B$58*'Calcul Re'!$B$46),100))^0.3)*'Calcul Re'!$B$61*(1-(0.41+0.35*'Calcul Re'!$B$60^4)*$A13/('Calcul Re'!$B$17*'Calcul Re'!$B$35))*PI()*'Calcul Re'!$B$59^2/4*SQRT(2*MAX($A13,0)*'Calcul Re'!$B$45) -> 0.0052451326 | L13: =(0.5961+0.0261*'Calcul Re'!$B$60^2-0.216*'Calcul Re'!$B$60^8+0.000521*(1000000*'Calcul Re'!$B$60/MAX(4*K13/(PI()*'Calcul Re'!$B$58*'Calcul Re'!$B$46),100))^0.7+(0.0188+0.0063*(19000*'Calcul Re'!$B$60/MAX(4*K13/(PI()*'Calcul Re'!$B$58*'Calcul Re'!$B$46),100))^0.8)*'Calcul Re'!$B$60^3.5*(1000000/MAX(4*K13/(PI()*'Calcul Re'!$B$58*'Calcul Re'!$B$46),100))^0.3)*'Calcul Re'!$B$61*(1-(0.41+0.35*'Calcul Re'!$B$60^4)*$A13/('Calcul Re'!$B$17*'Calcul Re'!$B$35))*PI()*'Calcul Re'!$B$59^2/4*SQRT(2*MAX($A13,0)*'Calcul Re'!$B$45) -> 0.0052453491 | M13: =(0.5961+0.0261*'Calcul Re'!$B$60^2-0.216*'Calcul Re'!$B$60^8+0.000521*(1000000*'Calcul Re'!$B$60/MAX(4*L13/(PI()*'Calcul Re'!$B$58*'Calcul Re'!$B$46),100))^0.7+(0.0188+0.0063*(19000*'Calcul Re'!$B$60/MAX(4*L13/(PI()*'Calcul Re'!$B$58*'Calcul Re'!$B$46),100))^0.8)*'Calcul Re'!$B$60^3.5*(1000000/MAX(4*L13/(PI()*'Calcul Re'!$B$58*'Calcul Re'!$B$46),100))^0.3)*'Calcul Re'!$B$61*(1-(0.41+0.35*'Calcul Re'!$B$60^4)*$A13/('Calcul Re'!$B$17*'Calcul Re'!$B$35))*PI()*'Calcul Re'!$B$59^2/4*SQRT(2*MAX($A13,0)*'Calcul Re'!$B$45) -> 0.0052453422 | N13: =(0.5961+0.0261*'Calcul Re'!$B$60^2-0.216*'Calcul Re'!$B$60^8+0.000521*(1000000*'Calcul Re'!$B$60/MAX(4*M13/(PI()*'Calcul Re'!$B$58*'Calcul Re'!$B$46),100))^0.7+(0.0188+0.0063*(19000*'Calcul Re'!$B$60/MAX(4*M13/(PI()*'Calcul Re'!$B$58*'Calcul Re'!$B$46),100))^0.8)*'Calcul Re'!$B$60^3.5*(1000000/MAX(4*M13/(PI()*'Calcul Re'!$B$58*'Calcul Re'!$B$46),100))^0.3)*'Calcul Re'!$B$61*(1-(0.41+0.35*'Calcul Re'!$B$60^4)*$A13/('Calcul Re'!$B$17*'Calcul Re'!$B$35))*PI()*'Calcul Re'!$B$59^2/4*SQRT(2*MAX($A13,0)*'Calcul Re'!$B$45) -> 0.0052453425 | O13: =(0.5961+0.0261*'Calcul Re'!$B$60^2-0.216*'Calcul Re'!$B$60^8+0.000521*(1000000*'Calcul Re'!$B$60/MAX(4*N13/(PI()*'Calcul Re'!$B$58*'Calcul Re'!$B$46),100))^0.7+(0.0188+0.0063*(19000*'Calcul Re'!$B$60/MAX(4*N13/(PI()*'Calcul Re'!$B$58*'Calcul Re'!$B$46),100))^0.8)*'Calcul Re'!$B$60^3.5*(1000000/MAX(4*N13/(PI()*'Calcul Re'!$B$58*'Calcul Re'!$B$46),100))^0.3)*'Calcul Re'!$B$61*(1-(0.41+0.35*'Calcul Re'!$B$60^4)*$A13/('Calcul Re'!$B$17*'Calcul Re'!$B$35))*PI()*'Calcul Re'!$B$59^2/4*SQRT(2*MAX($A13,0)*'Calcul Re'!$B$45) -> 0.0052453425 | P13: =(0.5961+0.0261*'Calcul Re'!$B$60^2-0.216*'Calcul Re'!$B$60^8+0.000521*(1000000*'Calcul Re'!$B$60/MAX(4*O13/(PI()*'Calcul Re'!$B$58*'Calcul Re'!$B$46),100))^0.7+(0.0188+0.0063*(19000*'Calcul Re'!$B$60/MAX(4*O13/(PI()*'Calcul Re'!$B$58*'Calcul Re'!$B$46),100))^0.8)*'Calcul Re'!$B$60^3.5*(1000000/MAX(4*O13/(PI()*'Calcul Re'!$B$58*'Calcul Re'!$B$46),100))^0.3)*'Calcul Re'!$B$61*(1-(0.41+0.35*'Calcul Re'!$B$60^4)*$A13/('Calcul Re'!$B$17*'Calcul Re'!$B$35))*PI()*'Calcul Re'!$B$59^2/4*SQRT(2*MAX($A13,0)*'Calcul Re'!$B$45) -> 0.0052453425 | Q13: =(0.5961+0.0261*'Calcul Re'!$B$60^2-0.216*'Calcul Re'!$B$60^8+0.000521*(1000000*'Calcul Re'!$B$60/MAX(4*P13/(PI()*'Calcul Re'!$B$58*'Calcul Re'!$B$46),100))^0.7+(0.0188+0.0063*(19000*'Calcul Re'!$B$60/MAX(4*P13/(PI()*'Calcul Re'!$B$58*'Calcul Re'!$B$46),100))^0.8)*'Calcul Re'!$B$60^3.5*(1000000/MAX(4*P13/(PI()*'Calcul Re'!$B$58*'Calcul Re'!$B$46),100))^0.3)*'Calcul Re'!$B$61*(1-(0.41+0.35*'Calcul Re'!$B$60^4)*$A13/('Calcul Re'!$B$17*'Calcul Re'!$B$35))*PI()*'Calcul Re'!$B$59^2/4*SQRT(2*MAX($A13,0)*'Calcul Re'!$B$45) -> 0.0052453425 | R13: =(0.5961+0.0261*'Calcul Re'!$B$60^2-0.216*'Calcul Re'!$B$60^8+0.000521*(1000000*'Calcul Re'!$B$60/MAX(4*Q13/(PI()*'Calcul Re'!$B$58*'Calcul Re'!$B$46),100))^0.7+(0.0188+0.0063*(19000*'Calcul Re'!$B$60/MAX(4*Q13/(PI()*'Calcul Re'!$B$58*'Calcul Re'!$B$46),100))^0.8)*'Calcul Re'!$B$60^3.5*(1000000/MAX(4*Q13/(PI()*'Calcul Re'!$B$58*'Calcul Re'!$B$46),100))^0.3)*'Calcul Re'!$B$61*(1-(0.41+0.35*'Calcul Re'!$B$60^4)*$A13/('Calcul Re'!$B$17*'Calcul Re'!$B$35))*PI()*'Calcul Re'!$B$59^2/4*SQRT(2*MAX($A13,0)*'Calcul Re'!$B$45) -> 0.0052453425
